Traceback (most recent call last):
  File "C:\Users\fwilden\AppData\Local\miniconda3\envs\jupyterbook\lib\site-packages\jupyter_cache\executors\utils.py", line 58, in single_nb_execution
    executenb(
  File "C:\Users\fwilden\AppData\Local\miniconda3\envs\jupyterbook\lib\site-packages\nbclient\client.py", line 1314, in execute
    return NotebookClient(nb=nb, resources=resources, km=km, **kwargs).execute()
  File "C:\Users\fwilden\AppData\Local\miniconda3\envs\jupyterbook\lib\site-packages\jupyter_core\utils\__init__.py", line 165, in wrapped
    return loop.run_until_complete(inner)
  File "C:\Users\fwilden\AppData\Local\miniconda3\envs\jupyterbook\lib\asyncio\base_events.py", line 649, in run_until_complete
    return future.result()
  File "C:\Users\fwilden\AppData\Local\miniconda3\envs\jupyterbook\lib\site-packages\nbclient\client.py", line 709, in async_execute
    await self.async_execute_cell(
  File "C:\Users\fwilden\AppData\Local\miniconda3\envs\jupyterbook\lib\site-packages\nbclient\client.py", line 1062, in async_execute_cell
    await self._check_raise_for_error(cell, cell_index, exec_reply)
  File "C:\Users\fwilden\AppData\Local\miniconda3\envs\jupyterbook\lib\site-packages\nbclient\client.py", line 918, in _check_raise_for_error
    raise CellExecutionError.from_cell_and_msg(cell, exec_reply_content)
nbclient.exceptions.CellExecutionError: An error occurred while executing the following cell:
------------------
import pandas as pd
import plotly.express as px
import datetime

df = pd.read_csv("bio.csv")
df['length'] = (pd.to_datetime(df['end'].replace("Present",datetime.datetime.now().strftime("%Y-%m"))) - pd.to_datetime(df['beginning'])).dt.days
df['text'] = 'Started: ' + df['beginning'].to_string() + '<br>Until: ' + df['end'].to_string()
fig = px.scatter_mapbox(df, lat='lat', lon='lon', color="type", hover_name="name", 
                     size="length",
                     hover_data={'type':False,
                                 'length':False,
                                 'beginning':True,
                                 'end':True,
                                 'lat':False,
                                 'lon':False},
                    mapbox_style="carto-positron")
fig.update_traces(hovertemplate='<b>%{hovertext}</b><br>Began: %{customdata[2]} <br>Until: %{customdata[3]}')
fig.update_layout(showlegend=False, margin={'t':0,'l':0,'b':0,'r':0})
fig.update_geos(fitbounds="locations")
fig.show()
------------------


[1;31m---------------------------------------------------------------------------[0m
[1;31mModuleNotFoundError[0m                       Traceback (most recent call last)
Cell [1;32mIn[2], line 1[0m
[1;32m----> 1[0m [38;5;28;01mimport[39;00m [38;5;21;01mpandas[39;00m [38;5;28;01mas[39;00m [38;5;21;01mpd[39;00m
[0;32m      2[0m [38;5;28;01mimport[39;00m [38;5;21;01mplotly[39;00m[38;5;21;01m.[39;00m[38;5;21;01mexpress[39;00m [38;5;28;01mas[39;00m [38;5;21;01mpx[39;00m
[0;32m      3[0m [38;5;28;01mimport[39;00m [38;5;21;01mdatetime[39;00m

[1;31mModuleNotFoundError[0m: No module named 'pandas'

